<?xml version="1.0"?>
<robot xmlns:xacro="http://ros.org/wiki/xacro">

    <!-- Properties -->
    <xacro:property name="big_box_mass"      value="1.00"/>
    <xacro:property name="big_box_size_x"    value="0.30"/>
    <xacro:property name="big_box_size_y"    value="${base_size_y}"/>
    <xacro:property name="big_box_size_z"    value="0.55"/>

    <xacro:property name="small_box_mass"    value="0.50"/>
    <xacro:property name="small_box_size_x"  value="0.20"/>
    <xacro:property name="small_box_size_y"  value="${base_size_y}"/>
    <xacro:property name="small_box_size_z"  value="0.30"/>

    <xacro:property name="head_plat_mass"    value="0.10"/>
    <xacro:property name="head_plat_size_x"  value="0.35"/>
    <xacro:property name="head_plat_size_y"  value="${base_size_y}"/>
    <xacro:property name="head_plat_size_z"  value="0.05"/>

    <xacro:property name="pole_mass"         value="0.20"/>
    <xacro:property name="pole_size_x"       value="0.13"/>
    <xacro:property name="pole_size_y"       value="0.06"/>
    <xacro:property name="pole_size_z"       value="1.00"/>

    <xacro:property name="sensor_plat_mass"             value="0.01"/>
    <xacro:property name="sensor_plat_size_x"           value="0.01"/>
    <xacro:property name="sensor_plat_size_y"           value="0.01"/>
    <xacro:property name="sensor_plat_size_z"           value="0.01"/>

    <xacro:property name="torso_sensor_plat_effort"     value="30" />
    <xacro:property name="torso_sensor_plat_velocity"   value="0.5" />

    <xacro:property name="camera_tilt_mass"    value="0.05"/>
    <xacro:property name="camera_tilt_size_x"  value="0.05"/>
    <xacro:property name="camera_tilt_size_y"  value="0.05"/>
    <xacro:property name="camera_tilt_size_z"  value="0.05"/>
    <xacro:property name="camera_pan_effort"      value="30"/>
    <xacro:property name="camera_pan_velocity"    value="0.5"/>
    <xacro:property name="camera_pan_lower_limit" value="-3.14"/>
    <xacro:property name="camera_pan_upper_limit" value="3.14"/>
    
  <xacro:macro name="torso" params="name parent">

    <!-- Main Torso Structure -->
    <link name="${name}">
        <!-- Large Main Box of the Torso -->
        <xacro:create_box
            m="${big_box_mass}"
            x="${big_box_size_x}"
            y="${big_box_size_y}"
            z="${big_box_size_z}">
            <origin xyz="-0.1 0 -0.225" rpy="0 0 0"/>
        </xacro:create_box>
        
        <!-- Small Auxiliary Box on the Torso -->
        <xacro:create_box
            m="${small_box_mass}"
            x="${small_box_size_x}"
            y="${small_box_size_y}"
            z="${small_box_size_z}">
            <origin xyz="0.15 0 -0.35" rpy="0 0 0"/>
        </xacro:create_box>
        
        <!-- Head Platform on the Torso -->
        <xacro:create_box
            m="${head_plat_mass}"
            x="${head_plat_size_x}"
            y="${head_plat_size_y}"
            z="${head_plat_size_z}">
            <origin xyz="-0.06 0 0.475" rpy="0 0 0"/>
        </xacro:create_box>
        
        <!-- Left Support Pole for Attachments -->
        <xacro:create_box
            m="${pole_mass}"
            x="${pole_size_x}"
            y="${pole_size_y}"
            z="${pole_size_z}">
            <origin xyz="-0.06 -0.18 0" rpy="0 0 0"/>
        </xacro:create_box>
        
        <!-- Right Support Pole for Attachments -->
        <xacro:create_box
            m="${pole_mass}"
            x="${pole_size_x}"
            y="${pole_size_y}"
            z="${pole_size_z}">
            <origin xyz="-0.06 0.18 0" rpy="0 0 0"/>
        </xacro:create_box>
        
        <!-- Torso Visual and Collision Representations -->
        <visual>
            <origin xyz="0 0 -0.5" rpy="1.57 0 0"/>
            <material name="dark_grey"/>
            <geometry>
                <mesh filename="package://hera_description/meshes/base/torso.stl" scale="0.001 0.001 0.001"/>
            </geometry>
        </visual>
        <collision>
            <origin xyz="0 0 -0.5" rpy="1.57 0 0"/>
            <material name="dark_grey"/>
            <geometry>
                <mesh filename="package://hera_description/meshes/base/torso.stl" scale="0.001 0.001 0.001"/>
            </geometry>
        </collision>
    </link>

    <!-- Sensor Platform -->
    <link name="${name}_sensor_platform">
        <!-- Sensor Platform Box -->
        <xacro:create_box
            m="${sensor_plat_mass}"
            x="${sensor_plat_size_x}"
            y="${sensor_plat_size_y}"
            z="${sensor_plat_size_z}">
            <origin xyz="0 0 0.0" rpy="1.57 3.14 0"/>
        </xacro:create_box>
        
        <!-- Sensor Platform Visual -->
        <visual>
            <origin xyz="0.0 0 0.0" rpy="1.57 3.14 0"/>
            <material name="white"/>
            <geometry>
                <mesh filename="package://hera_description/meshes/camera_meshes/dynamixel.stl" scale="0.001 0.001 0.001" color = "0.5 0.5 0.5 1"/>
            </geometry>
        </visual>
    </link>

    <!-- Fixed Joint from Parent to Main Torso Structure -->
    <joint name="joint_${parent}_to_${name}" type="fixed">
        <origin xyz="0 0 ${(base_size_z/2)+(pole_size_z/2)}" rpy="0 0 0"/>
        <parent link="${parent}"/>
        <child link="${name}"/>
    </joint>

    <!-- Fixed Joint from Main Torso Structure to Sensor Platform -->
    <joint name="joint_${name}_to_sensor_platform" type="fixed">
        <origin xyz="0.085 0 0.42" rpy="0 0 0"/>
        <parent link="${name}"/>
        <child link="${name}_sensor_platform"/>
        <axis xyz="0 -1 0"/>
        <limit effort="${torso_sensor_plat_effort}" velocity="${torso_sensor_plat_velocity}" lower="-2.0" upper="0.3"/>
    </joint>

    <!-- Camera Support Structure -->
    <link name="${name}_camera_tilt">
        <visual>
            <origin xyz="0 0 0.00" rpy="3.14 3.14 0"/>
            <geometry>
                <mesh filename="package://hera_description/meshes/camera_meshes/dynamixel.stl" scale="0.001 0.001 0.001" color = "0.5 0.5 0.5 1"/>
            </geometry>
            <material name="white"/>
        </visual>
        <inertial>
            <mass value="${camera_tilt_mass}"/>
            <inertia ixx="0.0001" ixy="0" ixz="0" iyy="0.0001" iyz="0" izz="0.0001"/>
        </inertial>
    </link>

    <!-- Pan Mechanism Link -->
    <link name="${name}_pan_mechanism_link">
        <visual>
            <origin xyz="0 0 0.015" rpy="0 0 0"/>
            <geometry>
                <box size="0.02 0.02 0.02"/> 
            </geometry>
            <material name="black"/> 
        </visual>
        <inertial>
            <mass value="0.1"/>
            <inertia ixx="0.0001" ixy="0" ixz="0" iyy="0.0001" iyz="0" izz="0.0001"/>
        </inertial>
    </link>

    <link name="${name}_connection_rod">
        <visual>
            <origin xyz="0 -0.025 0.025" rpy="0 0 0"/>
            <geometry>
                <cylinder length="0.03" radius="0.005"/> 
            </geometry>
            <material name="grey"/>
        </visual>
        <inertial>
            <mass value="0.02"/> 
            <inertia ixx="0.00001" ixy="0" ixz="0" iyy="0.00001" iyz="0" izz="0.00001"/>
        </inertial>
    </link>

    <!-- Joint Fixo que Conecta Sensor Platform à Haste -->
    <joint name="joint_camera_tilt" type="revolute">
        <origin xyz="0 -0.003 0.0" rpy="0 0 0"/>
        <parent link="${name}_sensor_platform"/>
        <child link="${name}_connection_rod"/>
        <axis xyz="0 -1 0"/>
        <limit effort="${torso_sensor_plat_effort}" velocity="${torso_sensor_plat_velocity}" lower="-2.0" upper="0.5"/>
    </joint>

    <!-- Joint Fixo que Conecta a Haste ao Pan Mechanism -->
    <joint name="joint_${name}_connection_rod_to_pan_mechanism" type="fixed">
        <origin xyz="0.005 0 0.05" rpy="0 0 0"/>
        <parent link="${name}_connection_rod"/>
        <child link="${name}_camera_tilt"/>
    </joint>

    <joint name="joint_camera_pan" type="revolute">
        <origin xyz="0 0 0.015" rpy="0 0 0"/>
        <parent link="${name}_camera_tilt"/>
        <child link="${name}_pan_mechanism_link"/>
        <axis xyz="0 0 1"/>
        <limit effort="${camera_pan_effort}" velocity="${camera_pan_velocity}" lower="${camera_pan_lower_limit}" upper="${camera_pan_upper_limit}"/>
    </joint>
</xacro:macro>

    <!--manip_support_link-->
    <xacro:macro name="create_manip_support_link" params="parent">
        <link name="manip_support_link">
            <visual>
                <origin xyz="0 0 0" rpy="0 0 0" />
                <geometry>
                    <mesh filename="package://hera_description/meshes/manipulator/manip_support.STL"/>
                </geometry>
                <material name="grey">
                    <color rgba="0.792156862745098 0.819607843137255 0.933333333333333 1" />
                </material>
            </visual>
            <collision>
                <origin xyz="0 0 0" rpy="0 0 0" />
                <geometry>
                    <mesh filename="package://hera_description/meshes/manipulator/manip_support.STL"/>
                </geometry>
            </collision>
            <xacro:inertial_manip_support_link mass="0.659217140679788"/>
        </link>

        <!--manip_support_joint--> 
        <joint name="manip_support_joint" type="fixed">
            <origin xyz="0.04525 0 0.0285" rpy="0 0 0" />
            <parent link="${parent}" />
            <child link="manip_support_link" />
            <axis xyz="0 0 0" />
            <limit lower="0" upper="0" effort="0" velocity="0" />
        </joint>
    </xacro:macro>

    <!--backrest_link-->
    <xacro:macro name="create_backrest_link" params="parent">
        <link name="backrest_link">
            <visual>
                <origin xyz="0 0 0" rpy="0 0 0" />
                <geometry>
                    <mesh filename="package://hera_description/meshes/manipulator/backrest.STL"/>
                </geometry>
                <material name="grey">
                    <color rgba="0.898039215686275 0.917647058823529 0.929411764705882 1" />
                </material>
            </visual>
            <collision>
                <origin xyz="0 0 0" rpy="0 0 0" />
                <geometry>
                    <mesh filename="package://hera_description/meshes/manipulator/backrest.STL"/>
                </geometry>
            </collision>
            <xacro:inertial_backrest_link mass="0.0709912944888601"/>
        </link>

        <!--backrest_joint-->
        <joint name="backrest_joint" type="fixed">
            <origin xyz="0.028 0.0066709 0.053" rpy="0 0 0" />
            <parent link="${parent}" />
            <child link="backrest_link" />
            <axis xyz="0 0 0" />
            <limit effort="0" velocity="0" />
        </joint>
    </xacro:macro>

</robot>